2020-04-17 01:55:18,621 DEBUG routes Add API resources
2020-04-17 01:55:18,624 DEBUG routes Added API resources
2020-04-17 01:55:18,625 DEBUG NeoBrain START
2020-04-17 01:55:26,655 ERROR flask.app Exception on /api/photos/7 [GET]
Traceback (most recent call last):
  File "C:\Users\romar\Anaconda3\lib\site-packages\sqlalchemy\engine\base.py", line 1193, in _execute_context
    context)
  File "C:\Users\romar\Anaconda3\lib\site-packages\sqlalchemy\engine\default.py", line 509, in do_execute
    cursor.execute(statement, parameters)
sqlite3.OperationalError: no such column: photos.created_date

The above exception was the direct cause of the following exception:

Traceback (most recent call last):
  File "C:\Users\romar\Anaconda3\lib\site-packages\flask\app.py", line 1813, in full_dispatch_request
    rv = self.dispatch_request()
  File "C:\Users\romar\Anaconda3\lib\site-packages\flask\app.py", line 1799, in dispatch_request
    return self.view_functions[rule.endpoint](**req.view_args)
  File "C:\Users\romar\Anaconda3\lib\site-packages\flask_restful\__init__.py", line 468, in wrapper
    resp = resource(*args, **kwargs)
  File "C:\Users\romar\Anaconda3\lib\site-packages\flask\views.py", line 88, in view
    return self.dispatch_request(*args, **kwargs)
  File "C:\Users\romar\Anaconda3\lib\site-packages\flask_restful\__init__.py", line 583, in dispatch_request
    resp = meth(*args, **kwargs)
  File "C:\NeoBrain\Server\resources\photos_resource.py", line 25, in get
    abort_if_photo_not_found(photo_id)
  File "C:\NeoBrain\Server\resources\photos_resource.py", line 14, in abort_if_photo_not_found
    photo = session.query(Photo).get(photo_id)
  File "C:\Users\romar\Anaconda3\lib\site-packages\sqlalchemy\orm\query.py", line 923, in get
    ident, loading.load_on_pk_identity)
  File "C:\Users\romar\Anaconda3\lib\site-packages\sqlalchemy\orm\query.py", line 1006, in _get_impl
    return db_load_fn(self, primary_key_identity)
  File "C:\Users\romar\Anaconda3\lib\site-packages\sqlalchemy\orm\loading.py", line 250, in load_on_pk_identity
    return q.one()
  File "C:\Users\romar\Anaconda3\lib\site-packages\sqlalchemy\orm\query.py", line 2947, in one
    ret = self.one_or_none()
  File "C:\Users\romar\Anaconda3\lib\site-packages\sqlalchemy\orm\query.py", line 2917, in one_or_none
    ret = list(self)
  File "C:\Users\romar\Anaconda3\lib\site-packages\sqlalchemy\orm\query.py", line 2988, in __iter__
    return self._execute_and_instances(context)
  File "C:\Users\romar\Anaconda3\lib\site-packages\sqlalchemy\orm\query.py", line 3011, in _execute_and_instances
    result = conn.execute(querycontext.statement, self._params)
  File "C:\Users\romar\Anaconda3\lib\site-packages\sqlalchemy\engine\base.py", line 948, in execute
    return meth(self, multiparams, params)
  File "C:\Users\romar\Anaconda3\lib\site-packages\sqlalchemy\sql\elements.py", line 269, in _execute_on_connection
    return connection._execute_clauseelement(self, multiparams, params)
  File "C:\Users\romar\Anaconda3\lib\site-packages\sqlalchemy\engine\base.py", line 1060, in _execute_clauseelement
    compiled_sql, distilled_params
  File "C:\Users\romar\Anaconda3\lib\site-packages\sqlalchemy\engine\base.py", line 1200, in _execute_context
    context)
  File "C:\Users\romar\Anaconda3\lib\site-packages\sqlalchemy\engine\base.py", line 1413, in _handle_dbapi_exception
    exc_info
  File "C:\Users\romar\Anaconda3\lib\site-packages\sqlalchemy\util\compat.py", line 265, in raise_from_cause
    reraise(type(exception), exception, tb=exc_tb, cause=cause)
  File "C:\Users\romar\Anaconda3\lib\site-packages\sqlalchemy\util\compat.py", line 248, in reraise
    raise value.with_traceback(tb)
  File "C:\Users\romar\Anaconda3\lib\site-packages\sqlalchemy\engine\base.py", line 1193, in _execute_context
    context)
  File "C:\Users\romar\Anaconda3\lib\site-packages\sqlalchemy\engine\default.py", line 509, in do_execute
    cursor.execute(statement, parameters)
sqlalchemy.exc.OperationalError: (sqlite3.OperationalError) no such column: photos.created_date [SQL: 'SELECT photos.id AS photos_id, photos.about AS photos_about, photos.data AS photos_data, photos.created_date AS photos_created_date \nFROM photos \nWHERE photos.id = ?'] [parameters: (7,)] (Background on this error at: http://sqlalche.me/e/e3q8)
2020-04-17 01:55:26,689 ERROR flask.app Exception on /api/photos/7 [GET]
Traceback (most recent call last):
  File "C:\Users\romar\Anaconda3\lib\site-packages\sqlalchemy\engine\base.py", line 1193, in _execute_context
    context)
  File "C:\Users\romar\Anaconda3\lib\site-packages\sqlalchemy\engine\default.py", line 509, in do_execute
    cursor.execute(statement, parameters)
sqlite3.OperationalError: no such column: photos.created_date

The above exception was the direct cause of the following exception:

Traceback (most recent call last):
  File "C:\Users\romar\Anaconda3\lib\site-packages\flask\app.py", line 1813, in full_dispatch_request
    rv = self.dispatch_request()
  File "C:\Users\romar\Anaconda3\lib\site-packages\flask\app.py", line 1799, in dispatch_request
    return self.view_functions[rule.endpoint](**req.view_args)
  File "C:\Users\romar\Anaconda3\lib\site-packages\flask_restful\__init__.py", line 468, in wrapper
    resp = resource(*args, **kwargs)
  File "C:\Users\romar\Anaconda3\lib\site-packages\flask\views.py", line 88, in view
    return self.dispatch_request(*args, **kwargs)
  File "C:\Users\romar\Anaconda3\lib\site-packages\flask_restful\__init__.py", line 583, in dispatch_request
    resp = meth(*args, **kwargs)
  File "C:\NeoBrain\Server\resources\photos_resource.py", line 25, in get
    abort_if_photo_not_found(photo_id)
  File "C:\NeoBrain\Server\resources\photos_resource.py", line 14, in abort_if_photo_not_found
    photo = session.query(Photo).get(photo_id)
  File "C:\Users\romar\Anaconda3\lib\site-packages\sqlalchemy\orm\query.py", line 923, in get
    ident, loading.load_on_pk_identity)
  File "C:\Users\romar\Anaconda3\lib\site-packages\sqlalchemy\orm\query.py", line 1006, in _get_impl
    return db_load_fn(self, primary_key_identity)
  File "C:\Users\romar\Anaconda3\lib\site-packages\sqlalchemy\orm\loading.py", line 250, in load_on_pk_identity
    return q.one()
  File "C:\Users\romar\Anaconda3\lib\site-packages\sqlalchemy\orm\query.py", line 2947, in one
    ret = self.one_or_none()
  File "C:\Users\romar\Anaconda3\lib\site-packages\sqlalchemy\orm\query.py", line 2917, in one_or_none
    ret = list(self)
  File "C:\Users\romar\Anaconda3\lib\site-packages\sqlalchemy\orm\query.py", line 2988, in __iter__
    return self._execute_and_instances(context)
  File "C:\Users\romar\Anaconda3\lib\site-packages\sqlalchemy\orm\query.py", line 3011, in _execute_and_instances
    result = conn.execute(querycontext.statement, self._params)
  File "C:\Users\romar\Anaconda3\lib\site-packages\sqlalchemy\engine\base.py", line 948, in execute
    return meth(self, multiparams, params)
  File "C:\Users\romar\Anaconda3\lib\site-packages\sqlalchemy\sql\elements.py", line 269, in _execute_on_connection
    return connection._execute_clauseelement(self, multiparams, params)
  File "C:\Users\romar\Anaconda3\lib\site-packages\sqlalchemy\engine\base.py", line 1060, in _execute_clauseelement
    compiled_sql, distilled_params
  File "C:\Users\romar\Anaconda3\lib\site-packages\sqlalchemy\engine\base.py", line 1200, in _execute_context
    context)
  File "C:\Users\romar\Anaconda3\lib\site-packages\sqlalchemy\engine\base.py", line 1413, in _handle_dbapi_exception
    exc_info
  File "C:\Users\romar\Anaconda3\lib\site-packages\sqlalchemy\util\compat.py", line 265, in raise_from_cause
    reraise(type(exception), exception, tb=exc_tb, cause=cause)
  File "C:\Users\romar\Anaconda3\lib\site-packages\sqlalchemy\util\compat.py", line 248, in reraise
    raise value.with_traceback(tb)
  File "C:\Users\romar\Anaconda3\lib\site-packages\sqlalchemy\engine\base.py", line 1193, in _execute_context
    context)
  File "C:\Users\romar\Anaconda3\lib\site-packages\sqlalchemy\engine\default.py", line 509, in do_execute
    cursor.execute(statement, parameters)
sqlalchemy.exc.OperationalError: (sqlite3.OperationalError) no such column: photos.created_date [SQL: 'SELECT photos.id AS photos_id, photos.about AS photos_about, photos.data AS photos_data, photos.created_date AS photos_created_date \nFROM photos \nWHERE photos.id = ?'] [parameters: (7,)] (Background on this error at: http://sqlalche.me/e/e3q8)
2020-04-17 01:55:26,691 ERROR flask.app Exception on /api/photos/7 [GET]
Traceback (most recent call last):
  File "C:\Users\romar\Anaconda3\lib\site-packages\sqlalchemy\engine\base.py", line 1193, in _execute_context
    context)
  File "C:\Users\romar\Anaconda3\lib\site-packages\sqlalchemy\engine\default.py", line 509, in do_execute
    cursor.execute(statement, parameters)
sqlite3.OperationalError: no such column: photos.created_date

The above exception was the direct cause of the following exception:

Traceback (most recent call last):
  File "C:\Users\romar\Anaconda3\lib\site-packages\flask\app.py", line 1813, in full_dispatch_request
    rv = self.dispatch_request()
  File "C:\Users\romar\Anaconda3\lib\site-packages\flask\app.py", line 1799, in dispatch_request
    return self.view_functions[rule.endpoint](**req.view_args)
  File "C:\Users\romar\Anaconda3\lib\site-packages\flask_restful\__init__.py", line 468, in wrapper
    resp = resource(*args, **kwargs)
  File "C:\Users\romar\Anaconda3\lib\site-packages\flask\views.py", line 88, in view
    return self.dispatch_request(*args, **kwargs)
  File "C:\Users\romar\Anaconda3\lib\site-packages\flask_restful\__init__.py", line 583, in dispatch_request
    resp = meth(*args, **kwargs)
  File "C:\NeoBrain\Server\resources\photos_resource.py", line 25, in get
    abort_if_photo_not_found(photo_id)
  File "C:\NeoBrain\Server\resources\photos_resource.py", line 14, in abort_if_photo_not_found
    photo = session.query(Photo).get(photo_id)
  File "C:\Users\romar\Anaconda3\lib\site-packages\sqlalchemy\orm\query.py", line 923, in get
    ident, loading.load_on_pk_identity)
  File "C:\Users\romar\Anaconda3\lib\site-packages\sqlalchemy\orm\query.py", line 1006, in _get_impl
    return db_load_fn(self, primary_key_identity)
  File "C:\Users\romar\Anaconda3\lib\site-packages\sqlalchemy\orm\loading.py", line 250, in load_on_pk_identity
    return q.one()
  File "C:\Users\romar\Anaconda3\lib\site-packages\sqlalchemy\orm\query.py", line 2947, in one
    ret = self.one_or_none()
  File "C:\Users\romar\Anaconda3\lib\site-packages\sqlalchemy\orm\query.py", line 2917, in one_or_none
    ret = list(self)
  File "C:\Users\romar\Anaconda3\lib\site-packages\sqlalchemy\orm\query.py", line 2988, in __iter__
    return self._execute_and_instances(context)
  File "C:\Users\romar\Anaconda3\lib\site-packages\sqlalchemy\orm\query.py", line 3011, in _execute_and_instances
    result = conn.execute(querycontext.statement, self._params)
  File "C:\Users\romar\Anaconda3\lib\site-packages\sqlalchemy\engine\base.py", line 948, in execute
    return meth(self, multiparams, params)
  File "C:\Users\romar\Anaconda3\lib\site-packages\sqlalchemy\sql\elements.py", line 269, in _execute_on_connection
    return connection._execute_clauseelement(self, multiparams, params)
  File "C:\Users\romar\Anaconda3\lib\site-packages\sqlalchemy\engine\base.py", line 1060, in _execute_clauseelement
    compiled_sql, distilled_params
  File "C:\Users\romar\Anaconda3\lib\site-packages\sqlalchemy\engine\base.py", line 1200, in _execute_context
    context)
  File "C:\Users\romar\Anaconda3\lib\site-packages\sqlalchemy\engine\base.py", line 1413, in _handle_dbapi_exception
    exc_info
  File "C:\Users\romar\Anaconda3\lib\site-packages\sqlalchemy\util\compat.py", line 265, in raise_from_cause
    reraise(type(exception), exception, tb=exc_tb, cause=cause)
  File "C:\Users\romar\Anaconda3\lib\site-packages\sqlalchemy\util\compat.py", line 248, in reraise
    raise value.with_traceback(tb)
  File "C:\Users\romar\Anaconda3\lib\site-packages\sqlalchemy\engine\base.py", line 1193, in _execute_context
    context)
  File "C:\Users\romar\Anaconda3\lib\site-packages\sqlalchemy\engine\default.py", line 509, in do_execute
    cursor.execute(statement, parameters)
sqlalchemy.exc.OperationalError: (sqlite3.OperationalError) no such column: photos.created_date [SQL: 'SELECT photos.id AS photos_id, photos.about AS photos_about, photos.data AS photos_data, photos.created_date AS photos_created_date \nFROM photos \nWHERE photos.id = ?'] [parameters: (7,)] (Background on this error at: http://sqlalche.me/e/e3q8)
2020-04-17 01:55:26,694 ERROR flask.app Exception on /api/photos/7 [GET]
Traceback (most recent call last):
  File "C:\Users\romar\Anaconda3\lib\site-packages\sqlalchemy\engine\base.py", line 1193, in _execute_context
    context)
  File "C:\Users\romar\Anaconda3\lib\site-packages\sqlalchemy\engine\default.py", line 509, in do_execute
    cursor.execute(statement, parameters)
sqlite3.OperationalError: no such column: photos.created_date

The above exception was the direct cause of the following exception:

Traceback (most recent call last):
  File "C:\Users\romar\Anaconda3\lib\site-packages\flask\app.py", line 1813, in full_dispatch_request
    rv = self.dispatch_request()
  File "C:\Users\romar\Anaconda3\lib\site-packages\flask\app.py", line 1799, in dispatch_request
    return self.view_functions[rule.endpoint](**req.view_args)
  File "C:\Users\romar\Anaconda3\lib\site-packages\flask_restful\__init__.py", line 468, in wrapper
    resp = resource(*args, **kwargs)
  File "C:\Users\romar\Anaconda3\lib\site-packages\flask\views.py", line 88, in view
    return self.dispatch_request(*args, **kwargs)
  File "C:\Users\romar\Anaconda3\lib\site-packages\flask_restful\__init__.py", line 583, in dispatch_request
    resp = meth(*args, **kwargs)
  File "C:\NeoBrain\Server\resources\photos_resource.py", line 25, in get
    abort_if_photo_not_found(photo_id)
  File "C:\NeoBrain\Server\resources\photos_resource.py", line 14, in abort_if_photo_not_found
    photo = session.query(Photo).get(photo_id)
  File "C:\Users\romar\Anaconda3\lib\site-packages\sqlalchemy\orm\query.py", line 923, in get
    ident, loading.load_on_pk_identity)
  File "C:\Users\romar\Anaconda3\lib\site-packages\sqlalchemy\orm\query.py", line 1006, in _get_impl
    return db_load_fn(self, primary_key_identity)
  File "C:\Users\romar\Anaconda3\lib\site-packages\sqlalchemy\orm\loading.py", line 250, in load_on_pk_identity
    return q.one()
  File "C:\Users\romar\Anaconda3\lib\site-packages\sqlalchemy\orm\query.py", line 2947, in one
    ret = self.one_or_none()
  File "C:\Users\romar\Anaconda3\lib\site-packages\sqlalchemy\orm\query.py", line 2917, in one_or_none
    ret = list(self)
  File "C:\Users\romar\Anaconda3\lib\site-packages\sqlalchemy\orm\query.py", line 2988, in __iter__
    return self._execute_and_instances(context)
  File "C:\Users\romar\Anaconda3\lib\site-packages\sqlalchemy\orm\query.py", line 3011, in _execute_and_instances
    result = conn.execute(querycontext.statement, self._params)
  File "C:\Users\romar\Anaconda3\lib\site-packages\sqlalchemy\engine\base.py", line 948, in execute
    return meth(self, multiparams, params)
  File "C:\Users\romar\Anaconda3\lib\site-packages\sqlalchemy\sql\elements.py", line 269, in _execute_on_connection
    return connection._execute_clauseelement(self, multiparams, params)
  File "C:\Users\romar\Anaconda3\lib\site-packages\sqlalchemy\engine\base.py", line 1060, in _execute_clauseelement
    compiled_sql, distilled_params
  File "C:\Users\romar\Anaconda3\lib\site-packages\sqlalchemy\engine\base.py", line 1200, in _execute_context
    context)
  File "C:\Users\romar\Anaconda3\lib\site-packages\sqlalchemy\engine\base.py", line 1413, in _handle_dbapi_exception
    exc_info
  File "C:\Users\romar\Anaconda3\lib\site-packages\sqlalchemy\util\compat.py", line 265, in raise_from_cause
    reraise(type(exception), exception, tb=exc_tb, cause=cause)
  File "C:\Users\romar\Anaconda3\lib\site-packages\sqlalchemy\util\compat.py", line 248, in reraise
    raise value.with_traceback(tb)
  File "C:\Users\romar\Anaconda3\lib\site-packages\sqlalchemy\engine\base.py", line 1193, in _execute_context
    context)
  File "C:\Users\romar\Anaconda3\lib\site-packages\sqlalchemy\engine\default.py", line 509, in do_execute
    cursor.execute(statement, parameters)
sqlalchemy.exc.OperationalError: (sqlite3.OperationalError) no such column: photos.created_date [SQL: 'SELECT photos.id AS photos_id, photos.about AS photos_about, photos.data AS photos_data, photos.created_date AS photos_created_date \nFROM photos \nWHERE photos.id = ?'] [parameters: (7,)] (Background on this error at: http://sqlalche.me/e/e3q8)
2020-04-17 01:55:36,195 ERROR flask.app Exception on /api/photos/7 [GET]
Traceback (most recent call last):
  File "C:\Users\romar\Anaconda3\lib\site-packages\sqlalchemy\engine\base.py", line 1193, in _execute_context
    context)
  File "C:\Users\romar\Anaconda3\lib\site-packages\sqlalchemy\engine\default.py", line 509, in do_execute
    cursor.execute(statement, parameters)
sqlite3.OperationalError: no such column: photos.created_date

The above exception was the direct cause of the following exception:

Traceback (most recent call last):
  File "C:\Users\romar\Anaconda3\lib\site-packages\flask\app.py", line 1813, in full_dispatch_request
    rv = self.dispatch_request()
  File "C:\Users\romar\Anaconda3\lib\site-packages\flask\app.py", line 1799, in dispatch_request
    return self.view_functions[rule.endpoint](**req.view_args)
  File "C:\Users\romar\Anaconda3\lib\site-packages\flask_restful\__init__.py", line 468, in wrapper
    resp = resource(*args, **kwargs)
  File "C:\Users\romar\Anaconda3\lib\site-packages\flask\views.py", line 88, in view
    return self.dispatch_request(*args, **kwargs)
  File "C:\Users\romar\Anaconda3\lib\site-packages\flask_restful\__init__.py", line 583, in dispatch_request
    resp = meth(*args, **kwargs)
  File "C:\NeoBrain\Server\resources\photos_resource.py", line 25, in get
    abort_if_photo_not_found(photo_id)
  File "C:\NeoBrain\Server\resources\photos_resource.py", line 14, in abort_if_photo_not_found
    photo = session.query(Photo).get(photo_id)
  File "C:\Users\romar\Anaconda3\lib\site-packages\sqlalchemy\orm\query.py", line 923, in get
    ident, loading.load_on_pk_identity)
  File "C:\Users\romar\Anaconda3\lib\site-packages\sqlalchemy\orm\query.py", line 1006, in _get_impl
    return db_load_fn(self, primary_key_identity)
  File "C:\Users\romar\Anaconda3\lib\site-packages\sqlalchemy\orm\loading.py", line 250, in load_on_pk_identity
    return q.one()
  File "C:\Users\romar\Anaconda3\lib\site-packages\sqlalchemy\orm\query.py", line 2947, in one
    ret = self.one_or_none()
  File "C:\Users\romar\Anaconda3\lib\site-packages\sqlalchemy\orm\query.py", line 2917, in one_or_none
    ret = list(self)
  File "C:\Users\romar\Anaconda3\lib\site-packages\sqlalchemy\orm\query.py", line 2988, in __iter__
    return self._execute_and_instances(context)
  File "C:\Users\romar\Anaconda3\lib\site-packages\sqlalchemy\orm\query.py", line 3011, in _execute_and_instances
    result = conn.execute(querycontext.statement, self._params)
  File "C:\Users\romar\Anaconda3\lib\site-packages\sqlalchemy\engine\base.py", line 948, in execute
    return meth(self, multiparams, params)
  File "C:\Users\romar\Anaconda3\lib\site-packages\sqlalchemy\sql\elements.py", line 269, in _execute_on_connection
    return connection._execute_clauseelement(self, multiparams, params)
  File "C:\Users\romar\Anaconda3\lib\site-packages\sqlalchemy\engine\base.py", line 1060, in _execute_clauseelement
    compiled_sql, distilled_params
  File "C:\Users\romar\Anaconda3\lib\site-packages\sqlalchemy\engine\base.py", line 1200, in _execute_context
    context)
  File "C:\Users\romar\Anaconda3\lib\site-packages\sqlalchemy\engine\base.py", line 1413, in _handle_dbapi_exception
    exc_info
  File "C:\Users\romar\Anaconda3\lib\site-packages\sqlalchemy\util\compat.py", line 265, in raise_from_cause
    reraise(type(exception), exception, tb=exc_tb, cause=cause)
  File "C:\Users\romar\Anaconda3\lib\site-packages\sqlalchemy\util\compat.py", line 248, in reraise
    raise value.with_traceback(tb)
  File "C:\Users\romar\Anaconda3\lib\site-packages\sqlalchemy\engine\base.py", line 1193, in _execute_context
    context)
  File "C:\Users\romar\Anaconda3\lib\site-packages\sqlalchemy\engine\default.py", line 509, in do_execute
    cursor.execute(statement, parameters)
sqlalchemy.exc.OperationalError: (sqlite3.OperationalError) no such column: photos.created_date [SQL: 'SELECT photos.id AS photos_id, photos.about AS photos_about, photos.data AS photos_data, photos.created_date AS photos_created_date \nFROM photos \nWHERE photos.id = ?'] [parameters: (7,)] (Background on this error at: http://sqlalche.me/e/e3q8)
2020-04-17 01:55:36,196 ERROR flask.app Exception on /api/photos/7 [GET]
Traceback (most recent call last):
  File "C:\Users\romar\Anaconda3\lib\site-packages\sqlalchemy\engine\base.py", line 1193, in _execute_context
    context)
  File "C:\Users\romar\Anaconda3\lib\site-packages\sqlalchemy\engine\default.py", line 509, in do_execute
    cursor.execute(statement, parameters)
sqlite3.OperationalError: no such column: photos.created_date

The above exception was the direct cause of the following exception:

Traceback (most recent call last):
  File "C:\Users\romar\Anaconda3\lib\site-packages\flask\app.py", line 1813, in full_dispatch_request
    rv = self.dispatch_request()
  File "C:\Users\romar\Anaconda3\lib\site-packages\flask\app.py", line 1799, in dispatch_request
    return self.view_functions[rule.endpoint](**req.view_args)
  File "C:\Users\romar\Anaconda3\lib\site-packages\flask_restful\__init__.py", line 468, in wrapper
    resp = resource(*args, **kwargs)
  File "C:\Users\romar\Anaconda3\lib\site-packages\flask\views.py", line 88, in view
    return self.dispatch_request(*args, **kwargs)
  File "C:\Users\romar\Anaconda3\lib\site-packages\flask_restful\__init__.py", line 583, in dispatch_request
    resp = meth(*args, **kwargs)
  File "C:\NeoBrain\Server\resources\photos_resource.py", line 25, in get
    abort_if_photo_not_found(photo_id)
  File "C:\NeoBrain\Server\resources\photos_resource.py", line 14, in abort_if_photo_not_found
    photo = session.query(Photo).get(photo_id)
  File "C:\Users\romar\Anaconda3\lib\site-packages\sqlalchemy\orm\query.py", line 923, in get
    ident, loading.load_on_pk_identity)
  File "C:\Users\romar\Anaconda3\lib\site-packages\sqlalchemy\orm\query.py", line 1006, in _get_impl
    return db_load_fn(self, primary_key_identity)
  File "C:\Users\romar\Anaconda3\lib\site-packages\sqlalchemy\orm\loading.py", line 250, in load_on_pk_identity
    return q.one()
  File "C:\Users\romar\Anaconda3\lib\site-packages\sqlalchemy\orm\query.py", line 2947, in one
    ret = self.one_or_none()
  File "C:\Users\romar\Anaconda3\lib\site-packages\sqlalchemy\orm\query.py", line 2917, in one_or_none
    ret = list(self)
  File "C:\Users\romar\Anaconda3\lib\site-packages\sqlalchemy\orm\query.py", line 2988, in __iter__
    return self._execute_and_instances(context)
  File "C:\Users\romar\Anaconda3\lib\site-packages\sqlalchemy\orm\query.py", line 3011, in _execute_and_instances
    result = conn.execute(querycontext.statement, self._params)
  File "C:\Users\romar\Anaconda3\lib\site-packages\sqlalchemy\engine\base.py", line 948, in execute
    return meth(self, multiparams, params)
  File "C:\Users\romar\Anaconda3\lib\site-packages\sqlalchemy\sql\elements.py", line 269, in _execute_on_connection
    return connection._execute_clauseelement(self, multiparams, params)
  File "C:\Users\romar\Anaconda3\lib\site-packages\sqlalchemy\engine\base.py", line 1060, in _execute_clauseelement
    compiled_sql, distilled_params
  File "C:\Users\romar\Anaconda3\lib\site-packages\sqlalchemy\engine\base.py", line 1200, in _execute_context
    context)
  File "C:\Users\romar\Anaconda3\lib\site-packages\sqlalchemy\engine\base.py", line 1413, in _handle_dbapi_exception
    exc_info
  File "C:\Users\romar\Anaconda3\lib\site-packages\sqlalchemy\util\compat.py", line 265, in raise_from_cause
    reraise(type(exception), exception, tb=exc_tb, cause=cause)
  File "C:\Users\romar\Anaconda3\lib\site-packages\sqlalchemy\util\compat.py", line 248, in reraise
    raise value.with_traceback(tb)
  File "C:\Users\romar\Anaconda3\lib\site-packages\sqlalchemy\engine\base.py", line 1193, in _execute_context
    context)
  File "C:\Users\romar\Anaconda3\lib\site-packages\sqlalchemy\engine\default.py", line 509, in do_execute
    cursor.execute(statement, parameters)
sqlalchemy.exc.OperationalError: (sqlite3.OperationalError) no such column: photos.created_date [SQL: 'SELECT photos.id AS photos_id, photos.about AS photos_about, photos.data AS photos_data, photos.created_date AS photos_created_date \nFROM photos \nWHERE photos.id = ?'] [parameters: (7,)] (Background on this error at: http://sqlalche.me/e/e3q8)
2020-04-17 01:55:38,994 ERROR flask.app Exception on /api/photos/7 [GET]
Traceback (most recent call last):
  File "C:\Users\romar\Anaconda3\lib\site-packages\sqlalchemy\engine\base.py", line 1193, in _execute_context
    context)
  File "C:\Users\romar\Anaconda3\lib\site-packages\sqlalchemy\engine\default.py", line 509, in do_execute
    cursor.execute(statement, parameters)
sqlite3.OperationalError: no such column: photos.created_date

The above exception was the direct cause of the following exception:

Traceback (most recent call last):
  File "C:\Users\romar\Anaconda3\lib\site-packages\flask\app.py", line 1813, in full_dispatch_request
    rv = self.dispatch_request()
  File "C:\Users\romar\Anaconda3\lib\site-packages\flask\app.py", line 1799, in dispatch_request
    return self.view_functions[rule.endpoint](**req.view_args)
  File "C:\Users\romar\Anaconda3\lib\site-packages\flask_restful\__init__.py", line 468, in wrapper
    resp = resource(*args, **kwargs)
  File "C:\Users\romar\Anaconda3\lib\site-packages\flask\views.py", line 88, in view
    return self.dispatch_request(*args, **kwargs)
  File "C:\Users\romar\Anaconda3\lib\site-packages\flask_restful\__init__.py", line 583, in dispatch_request
    resp = meth(*args, **kwargs)
  File "C:\NeoBrain\Server\resources\photos_resource.py", line 25, in get
    abort_if_photo_not_found(photo_id)
  File "C:\NeoBrain\Server\resources\photos_resource.py", line 14, in abort_if_photo_not_found
    photo = session.query(Photo).get(photo_id)
  File "C:\Users\romar\Anaconda3\lib\site-packages\sqlalchemy\orm\query.py", line 923, in get
    ident, loading.load_on_pk_identity)
  File "C:\Users\romar\Anaconda3\lib\site-packages\sqlalchemy\orm\query.py", line 1006, in _get_impl
    return db_load_fn(self, primary_key_identity)
  File "C:\Users\romar\Anaconda3\lib\site-packages\sqlalchemy\orm\loading.py", line 250, in load_on_pk_identity
    return q.one()
  File "C:\Users\romar\Anaconda3\lib\site-packages\sqlalchemy\orm\query.py", line 2947, in one
    ret = self.one_or_none()
  File "C:\Users\romar\Anaconda3\lib\site-packages\sqlalchemy\orm\query.py", line 2917, in one_or_none
    ret = list(self)
  File "C:\Users\romar\Anaconda3\lib\site-packages\sqlalchemy\orm\query.py", line 2988, in __iter__
    return self._execute_and_instances(context)
  File "C:\Users\romar\Anaconda3\lib\site-packages\sqlalchemy\orm\query.py", line 3011, in _execute_and_instances
    result = conn.execute(querycontext.statement, self._params)
  File "C:\Users\romar\Anaconda3\lib\site-packages\sqlalchemy\engine\base.py", line 948, in execute
    return meth(self, multiparams, params)
  File "C:\Users\romar\Anaconda3\lib\site-packages\sqlalchemy\sql\elements.py", line 269, in _execute_on_connection
    return connection._execute_clauseelement(self, multiparams, params)
  File "C:\Users\romar\Anaconda3\lib\site-packages\sqlalchemy\engine\base.py", line 1060, in _execute_clauseelement
    compiled_sql, distilled_params
  File "C:\Users\romar\Anaconda3\lib\site-packages\sqlalchemy\engine\base.py", line 1200, in _execute_context
    context)
  File "C:\Users\romar\Anaconda3\lib\site-packages\sqlalchemy\engine\base.py", line 1413, in _handle_dbapi_exception
    exc_info
  File "C:\Users\romar\Anaconda3\lib\site-packages\sqlalchemy\util\compat.py", line 265, in raise_from_cause
    reraise(type(exception), exception, tb=exc_tb, cause=cause)
  File "C:\Users\romar\Anaconda3\lib\site-packages\sqlalchemy\util\compat.py", line 248, in reraise
    raise value.with_traceback(tb)
  File "C:\Users\romar\Anaconda3\lib\site-packages\sqlalchemy\engine\base.py", line 1193, in _execute_context
    context)
  File "C:\Users\romar\Anaconda3\lib\site-packages\sqlalchemy\engine\default.py", line 509, in do_execute
    cursor.execute(statement, parameters)
sqlalchemy.exc.OperationalError: (sqlite3.OperationalError) no such column: photos.created_date [SQL: 'SELECT photos.id AS photos_id, photos.about AS photos_about, photos.data AS photos_data, photos.created_date AS photos_created_date \nFROM photos \nWHERE photos.id = ?'] [parameters: (7,)] (Background on this error at: http://sqlalche.me/e/e3q8)
2020-04-17 01:55:39,006 ERROR flask.app Exception on /api/photos/7 [GET]
Traceback (most recent call last):
  File "C:\Users\romar\Anaconda3\lib\site-packages\sqlalchemy\engine\base.py", line 1193, in _execute_context
    context)
  File "C:\Users\romar\Anaconda3\lib\site-packages\sqlalchemy\engine\default.py", line 509, in do_execute
    cursor.execute(statement, parameters)
sqlite3.OperationalError: no such column: photos.created_date

The above exception was the direct cause of the following exception:

Traceback (most recent call last):
  File "C:\Users\romar\Anaconda3\lib\site-packages\flask\app.py", line 1813, in full_dispatch_request
    rv = self.dispatch_request()
  File "C:\Users\romar\Anaconda3\lib\site-packages\flask\app.py", line 1799, in dispatch_request
    return self.view_functions[rule.endpoint](**req.view_args)
  File "C:\Users\romar\Anaconda3\lib\site-packages\flask_restful\__init__.py", line 468, in wrapper
    resp = resource(*args, **kwargs)
  File "C:\Users\romar\Anaconda3\lib\site-packages\flask\views.py", line 88, in view
    return self.dispatch_request(*args, **kwargs)
  File "C:\Users\romar\Anaconda3\lib\site-packages\flask_restful\__init__.py", line 583, in dispatch_request
    resp = meth(*args, **kwargs)
  File "C:\NeoBrain\Server\resources\photos_resource.py", line 25, in get
    abort_if_photo_not_found(photo_id)
  File "C:\NeoBrain\Server\resources\photos_resource.py", line 14, in abort_if_photo_not_found
    photo = session.query(Photo).get(photo_id)
  File "C:\Users\romar\Anaconda3\lib\site-packages\sqlalchemy\orm\query.py", line 923, in get
    ident, loading.load_on_pk_identity)
  File "C:\Users\romar\Anaconda3\lib\site-packages\sqlalchemy\orm\query.py", line 1006, in _get_impl
    return db_load_fn(self, primary_key_identity)
  File "C:\Users\romar\Anaconda3\lib\site-packages\sqlalchemy\orm\loading.py", line 250, in load_on_pk_identity
    return q.one()
  File "C:\Users\romar\Anaconda3\lib\site-packages\sqlalchemy\orm\query.py", line 2947, in one
    ret = self.one_or_none()
  File "C:\Users\romar\Anaconda3\lib\site-packages\sqlalchemy\orm\query.py", line 2917, in one_or_none
    ret = list(self)
  File "C:\Users\romar\Anaconda3\lib\site-packages\sqlalchemy\orm\query.py", line 2988, in __iter__
    return self._execute_and_instances(context)
  File "C:\Users\romar\Anaconda3\lib\site-packages\sqlalchemy\orm\query.py", line 3011, in _execute_and_instances
    result = conn.execute(querycontext.statement, self._params)
  File "C:\Users\romar\Anaconda3\lib\site-packages\sqlalchemy\engine\base.py", line 948, in execute
    return meth(self, multiparams, params)
  File "C:\Users\romar\Anaconda3\lib\site-packages\sqlalchemy\sql\elements.py", line 269, in _execute_on_connection
    return connection._execute_clauseelement(self, multiparams, params)
  File "C:\Users\romar\Anaconda3\lib\site-packages\sqlalchemy\engine\base.py", line 1060, in _execute_clauseelement
    compiled_sql, distilled_params
  File "C:\Users\romar\Anaconda3\lib\site-packages\sqlalchemy\engine\base.py", line 1200, in _execute_context
    context)
  File "C:\Users\romar\Anaconda3\lib\site-packages\sqlalchemy\engine\base.py", line 1413, in _handle_dbapi_exception
    exc_info
  File "C:\Users\romar\Anaconda3\lib\site-packages\sqlalchemy\util\compat.py", line 265, in raise_from_cause
    reraise(type(exception), exception, tb=exc_tb, cause=cause)
  File "C:\Users\romar\Anaconda3\lib\site-packages\sqlalchemy\util\compat.py", line 248, in reraise
    raise value.with_traceback(tb)
  File "C:\Users\romar\Anaconda3\lib\site-packages\sqlalchemy\engine\base.py", line 1193, in _execute_context
    context)
  File "C:\Users\romar\Anaconda3\lib\site-packages\sqlalchemy\engine\default.py", line 509, in do_execute
    cursor.execute(statement, parameters)
sqlalchemy.exc.OperationalError: (sqlite3.OperationalError) no such column: photos.created_date [SQL: 'SELECT photos.id AS photos_id, photos.about AS photos_about, photos.data AS photos_data, photos.created_date AS photos_created_date \nFROM photos \nWHERE photos.id = ?'] [parameters: (7,)] (Background on this error at: http://sqlalche.me/e/e3q8)
2020-04-17 01:55:39,006 ERROR flask.app Exception on /api/photos/7 [GET]
Traceback (most recent call last):
  File "C:\Users\romar\Anaconda3\lib\site-packages\sqlalchemy\engine\base.py", line 1193, in _execute_context
    context)
  File "C:\Users\romar\Anaconda3\lib\site-packages\sqlalchemy\engine\default.py", line 509, in do_execute
    cursor.execute(statement, parameters)
sqlite3.OperationalError: no such column: photos.created_date

The above exception was the direct cause of the following exception:

Traceback (most recent call last):
  File "C:\Users\romar\Anaconda3\lib\site-packages\flask\app.py", line 1813, in full_dispatch_request
    rv = self.dispatch_request()
  File "C:\Users\romar\Anaconda3\lib\site-packages\flask\app.py", line 1799, in dispatch_request
    return self.view_functions[rule.endpoint](**req.view_args)
  File "C:\Users\romar\Anaconda3\lib\site-packages\flask_restful\__init__.py", line 468, in wrapper
    resp = resource(*args, **kwargs)
  File "C:\Users\romar\Anaconda3\lib\site-packages\flask\views.py", line 88, in view
    return self.dispatch_request(*args, **kwargs)
  File "C:\Users\romar\Anaconda3\lib\site-packages\flask_restful\__init__.py", line 583, in dispatch_request
    resp = meth(*args, **kwargs)
  File "C:\NeoBrain\Server\resources\photos_resource.py", line 25, in get
    abort_if_photo_not_found(photo_id)
  File "C:\NeoBrain\Server\resources\photos_resource.py", line 14, in abort_if_photo_not_found
    photo = session.query(Photo).get(photo_id)
  File "C:\Users\romar\Anaconda3\lib\site-packages\sqlalchemy\orm\query.py", line 923, in get
    ident, loading.load_on_pk_identity)
  File "C:\Users\romar\Anaconda3\lib\site-packages\sqlalchemy\orm\query.py", line 1006, in _get_impl
    return db_load_fn(self, primary_key_identity)
  File "C:\Users\romar\Anaconda3\lib\site-packages\sqlalchemy\orm\loading.py", line 250, in load_on_pk_identity
    return q.one()
  File "C:\Users\romar\Anaconda3\lib\site-packages\sqlalchemy\orm\query.py", line 2947, in one
    ret = self.one_or_none()
  File "C:\Users\romar\Anaconda3\lib\site-packages\sqlalchemy\orm\query.py", line 2917, in one_or_none
    ret = list(self)
  File "C:\Users\romar\Anaconda3\lib\site-packages\sqlalchemy\orm\query.py", line 2988, in __iter__
    return self._execute_and_instances(context)
  File "C:\Users\romar\Anaconda3\lib\site-packages\sqlalchemy\orm\query.py", line 3011, in _execute_and_instances
    result = conn.execute(querycontext.statement, self._params)
  File "C:\Users\romar\Anaconda3\lib\site-packages\sqlalchemy\engine\base.py", line 948, in execute
    return meth(self, multiparams, params)
  File "C:\Users\romar\Anaconda3\lib\site-packages\sqlalchemy\sql\elements.py", line 269, in _execute_on_connection
    return connection._execute_clauseelement(self, multiparams, params)
  File "C:\Users\romar\Anaconda3\lib\site-packages\sqlalchemy\engine\base.py", line 1060, in _execute_clauseelement
    compiled_sql, distilled_params
  File "C:\Users\romar\Anaconda3\lib\site-packages\sqlalchemy\engine\base.py", line 1200, in _execute_context
    context)
  File "C:\Users\romar\Anaconda3\lib\site-packages\sqlalchemy\engine\base.py", line 1413, in _handle_dbapi_exception
    exc_info
  File "C:\Users\romar\Anaconda3\lib\site-packages\sqlalchemy\util\compat.py", line 265, in raise_from_cause
    reraise(type(exception), exception, tb=exc_tb, cause=cause)
  File "C:\Users\romar\Anaconda3\lib\site-packages\sqlalchemy\util\compat.py", line 248, in reraise
    raise value.with_traceback(tb)
  File "C:\Users\romar\Anaconda3\lib\site-packages\sqlalchemy\engine\base.py", line 1193, in _execute_context
    context)
  File "C:\Users\romar\Anaconda3\lib\site-packages\sqlalchemy\engine\default.py", line 509, in do_execute
    cursor.execute(statement, parameters)
sqlalchemy.exc.OperationalError: (sqlite3.OperationalError) no such column: photos.created_date [SQL: 'SELECT photos.id AS photos_id, photos.about AS photos_about, photos.data AS photos_data, photos.created_date AS photos_created_date \nFROM photos \nWHERE photos.id = ?'] [parameters: (7,)] (Background on this error at: http://sqlalche.me/e/e3q8)
2020-04-17 01:55:39,069 ERROR flask.app Exception on /api/photos/7 [GET]
Traceback (most recent call last):
  File "C:\Users\romar\Anaconda3\lib\site-packages\sqlalchemy\engine\base.py", line 1193, in _execute_context
    context)
  File "C:\Users\romar\Anaconda3\lib\site-packages\sqlalchemy\engine\default.py", line 509, in do_execute
    cursor.execute(statement, parameters)
sqlite3.OperationalError: no such column: photos.created_date

The above exception was the direct cause of the following exception:

Traceback (most recent call last):
  File "C:\Users\romar\Anaconda3\lib\site-packages\flask\app.py", line 1813, in full_dispatch_request
    rv = self.dispatch_request()
  File "C:\Users\romar\Anaconda3\lib\site-packages\flask\app.py", line 1799, in dispatch_request
    return self.view_functions[rule.endpoint](**req.view_args)
  File "C:\Users\romar\Anaconda3\lib\site-packages\flask_restful\__init__.py", line 468, in wrapper
    resp = resource(*args, **kwargs)
  File "C:\Users\romar\Anaconda3\lib\site-packages\flask\views.py", line 88, in view
    return self.dispatch_request(*args, **kwargs)
  File "C:\Users\romar\Anaconda3\lib\site-packages\flask_restful\__init__.py", line 583, in dispatch_request
    resp = meth(*args, **kwargs)
  File "C:\NeoBrain\Server\resources\photos_resource.py", line 25, in get
    abort_if_photo_not_found(photo_id)
  File "C:\NeoBrain\Server\resources\photos_resource.py", line 14, in abort_if_photo_not_found
    photo = session.query(Photo).get(photo_id)
  File "C:\Users\romar\Anaconda3\lib\site-packages\sqlalchemy\orm\query.py", line 923, in get
    ident, loading.load_on_pk_identity)
  File "C:\Users\romar\Anaconda3\lib\site-packages\sqlalchemy\orm\query.py", line 1006, in _get_impl
    return db_load_fn(self, primary_key_identity)
  File "C:\Users\romar\Anaconda3\lib\site-packages\sqlalchemy\orm\loading.py", line 250, in load_on_pk_identity
    return q.one()
  File "C:\Users\romar\Anaconda3\lib\site-packages\sqlalchemy\orm\query.py", line 2947, in one
    ret = self.one_or_none()
  File "C:\Users\romar\Anaconda3\lib\site-packages\sqlalchemy\orm\query.py", line 2917, in one_or_none
    ret = list(self)
  File "C:\Users\romar\Anaconda3\lib\site-packages\sqlalchemy\orm\query.py", line 2988, in __iter__
    return self._execute_and_instances(context)
  File "C:\Users\romar\Anaconda3\lib\site-packages\sqlalchemy\orm\query.py", line 3011, in _execute_and_instances
    result = conn.execute(querycontext.statement, self._params)
  File "C:\Users\romar\Anaconda3\lib\site-packages\sqlalchemy\engine\base.py", line 948, in execute
    return meth(self, multiparams, params)
  File "C:\Users\romar\Anaconda3\lib\site-packages\sqlalchemy\sql\elements.py", line 269, in _execute_on_connection
    return connection._execute_clauseelement(self, multiparams, params)
  File "C:\Users\romar\Anaconda3\lib\site-packages\sqlalchemy\engine\base.py", line 1060, in _execute_clauseelement
    compiled_sql, distilled_params
  File "C:\Users\romar\Anaconda3\lib\site-packages\sqlalchemy\engine\base.py", line 1200, in _execute_context
    context)
  File "C:\Users\romar\Anaconda3\lib\site-packages\sqlalchemy\engine\base.py", line 1413, in _handle_dbapi_exception
    exc_info
  File "C:\Users\romar\Anaconda3\lib\site-packages\sqlalchemy\util\compat.py", line 265, in raise_from_cause
    reraise(type(exception), exception, tb=exc_tb, cause=cause)
  File "C:\Users\romar\Anaconda3\lib\site-packages\sqlalchemy\util\compat.py", line 248, in reraise
    raise value.with_traceback(tb)
  File "C:\Users\romar\Anaconda3\lib\site-packages\sqlalchemy\engine\base.py", line 1193, in _execute_context
    context)
  File "C:\Users\romar\Anaconda3\lib\site-packages\sqlalchemy\engine\default.py", line 509, in do_execute
    cursor.execute(statement, parameters)
sqlalchemy.exc.OperationalError: (sqlite3.OperationalError) no such column: photos.created_date [SQL: 'SELECT photos.id AS photos_id, photos.about AS photos_about, photos.data AS photos_data, photos.created_date AS photos_created_date \nFROM photos \nWHERE photos.id = ?'] [parameters: (7,)] (Background on this error at: http://sqlalche.me/e/e3q8)
2020-04-17 01:55:39,074 ERROR flask.app Exception on /api/photos/7 [GET]
Traceback (most recent call last):
  File "C:\Users\romar\Anaconda3\lib\site-packages\sqlalchemy\engine\base.py", line 1193, in _execute_context
    context)
  File "C:\Users\romar\Anaconda3\lib\site-packages\sqlalchemy\engine\default.py", line 509, in do_execute
    cursor.execute(statement, parameters)
sqlite3.OperationalError: no such column: photos.created_date

The above exception was the direct cause of the following exception:

Traceback (most recent call last):
  File "C:\Users\romar\Anaconda3\lib\site-packages\flask\app.py", line 1813, in full_dispatch_request
    rv = self.dispatch_request()
  File "C:\Users\romar\Anaconda3\lib\site-packages\flask\app.py", line 1799, in dispatch_request
    return self.view_functions[rule.endpoint](**req.view_args)
  File "C:\Users\romar\Anaconda3\lib\site-packages\flask_restful\__init__.py", line 468, in wrapper
    resp = resource(*args, **kwargs)
  File "C:\Users\romar\Anaconda3\lib\site-packages\flask\views.py", line 88, in view
    return self.dispatch_request(*args, **kwargs)
  File "C:\Users\romar\Anaconda3\lib\site-packages\flask_restful\__init__.py", line 583, in dispatch_request
    resp = meth(*args, **kwargs)
  File "C:\NeoBrain\Server\resources\photos_resource.py", line 25, in get
    abort_if_photo_not_found(photo_id)
  File "C:\NeoBrain\Server\resources\photos_resource.py", line 14, in abort_if_photo_not_found
    photo = session.query(Photo).get(photo_id)
  File "C:\Users\romar\Anaconda3\lib\site-packages\sqlalchemy\orm\query.py", line 923, in get
    ident, loading.load_on_pk_identity)
  File "C:\Users\romar\Anaconda3\lib\site-packages\sqlalchemy\orm\query.py", line 1006, in _get_impl
    return db_load_fn(self, primary_key_identity)
  File "C:\Users\romar\Anaconda3\lib\site-packages\sqlalchemy\orm\loading.py", line 250, in load_on_pk_identity
    return q.one()
  File "C:\Users\romar\Anaconda3\lib\site-packages\sqlalchemy\orm\query.py", line 2947, in one
    ret = self.one_or_none()
  File "C:\Users\romar\Anaconda3\lib\site-packages\sqlalchemy\orm\query.py", line 2917, in one_or_none
    ret = list(self)
  File "C:\Users\romar\Anaconda3\lib\site-packages\sqlalchemy\orm\query.py", line 2988, in __iter__
    return self._execute_and_instances(context)
  File "C:\Users\romar\Anaconda3\lib\site-packages\sqlalchemy\orm\query.py", line 3011, in _execute_and_instances
    result = conn.execute(querycontext.statement, self._params)
  File "C:\Users\romar\Anaconda3\lib\site-packages\sqlalchemy\engine\base.py", line 948, in execute
    return meth(self, multiparams, params)
  File "C:\Users\romar\Anaconda3\lib\site-packages\sqlalchemy\sql\elements.py", line 269, in _execute_on_connection
    return connection._execute_clauseelement(self, multiparams, params)
  File "C:\Users\romar\Anaconda3\lib\site-packages\sqlalchemy\engine\base.py", line 1060, in _execute_clauseelement
    compiled_sql, distilled_params
  File "C:\Users\romar\Anaconda3\lib\site-packages\sqlalchemy\engine\base.py", line 1200, in _execute_context
    context)
  File "C:\Users\romar\Anaconda3\lib\site-packages\sqlalchemy\engine\base.py", line 1413, in _handle_dbapi_exception
    exc_info
  File "C:\Users\romar\Anaconda3\lib\site-packages\sqlalchemy\util\compat.py", line 265, in raise_from_cause
    reraise(type(exception), exception, tb=exc_tb, cause=cause)
  File "C:\Users\romar\Anaconda3\lib\site-packages\sqlalchemy\util\compat.py", line 248, in reraise
    raise value.with_traceback(tb)
  File "C:\Users\romar\Anaconda3\lib\site-packages\sqlalchemy\engine\base.py", line 1193, in _execute_context
    context)
  File "C:\Users\romar\Anaconda3\lib\site-packages\sqlalchemy\engine\default.py", line 509, in do_execute
    cursor.execute(statement, parameters)
sqlalchemy.exc.OperationalError: (sqlite3.OperationalError) no such column: photos.created_date [SQL: 'SELECT photos.id AS photos_id, photos.about AS photos_about, photos.data AS photos_data, photos.created_date AS photos_created_date \nFROM photos \nWHERE photos.id = ?'] [parameters: (7,)] (Background on this error at: http://sqlalche.me/e/e3q8)
2020-04-17 01:55:39,086 ERROR flask.app Exception on /api/photos/7 [GET]
Traceback (most recent call last):
  File "C:\Users\romar\Anaconda3\lib\site-packages\sqlalchemy\engine\base.py", line 1193, in _execute_context
    context)
  File "C:\Users\romar\Anaconda3\lib\site-packages\sqlalchemy\engine\default.py", line 509, in do_execute
    cursor.execute(statement, parameters)
sqlite3.OperationalError: no such column: photos.created_date

The above exception was the direct cause of the following exception:

Traceback (most recent call last):
  File "C:\Users\romar\Anaconda3\lib\site-packages\flask\app.py", line 1813, in full_dispatch_request
    rv = self.dispatch_request()
  File "C:\Users\romar\Anaconda3\lib\site-packages\flask\app.py", line 1799, in dispatch_request
    return self.view_functions[rule.endpoint](**req.view_args)
  File "C:\Users\romar\Anaconda3\lib\site-packages\flask_restful\__init__.py", line 468, in wrapper
    resp = resource(*args, **kwargs)
  File "C:\Users\romar\Anaconda3\lib\site-packages\flask\views.py", line 88, in view
    return self.dispatch_request(*args, **kwargs)
  File "C:\Users\romar\Anaconda3\lib\site-packages\flask_restful\__init__.py", line 583, in dispatch_request
    resp = meth(*args, **kwargs)
  File "C:\NeoBrain\Server\resources\photos_resource.py", line 25, in get
    abort_if_photo_not_found(photo_id)
  File "C:\NeoBrain\Server\resources\photos_resource.py", line 14, in abort_if_photo_not_found
    photo = session.query(Photo).get(photo_id)
  File "C:\Users\romar\Anaconda3\lib\site-packages\sqlalchemy\orm\query.py", line 923, in get
    ident, loading.load_on_pk_identity)
  File "C:\Users\romar\Anaconda3\lib\site-packages\sqlalchemy\orm\query.py", line 1006, in _get_impl
    return db_load_fn(self, primary_key_identity)
  File "C:\Users\romar\Anaconda3\lib\site-packages\sqlalchemy\orm\loading.py", line 250, in load_on_pk_identity
    return q.one()
  File "C:\Users\romar\Anaconda3\lib\site-packages\sqlalchemy\orm\query.py", line 2947, in one
    ret = self.one_or_none()
  File "C:\Users\romar\Anaconda3\lib\site-packages\sqlalchemy\orm\query.py", line 2917, in one_or_none
    ret = list(self)
  File "C:\Users\romar\Anaconda3\lib\site-packages\sqlalchemy\orm\query.py", line 2988, in __iter__
    return self._execute_and_instances(context)
  File "C:\Users\romar\Anaconda3\lib\site-packages\sqlalchemy\orm\query.py", line 3011, in _execute_and_instances
    result = conn.execute(querycontext.statement, self._params)
  File "C:\Users\romar\Anaconda3\lib\site-packages\sqlalchemy\engine\base.py", line 948, in execute
    return meth(self, multiparams, params)
  File "C:\Users\romar\Anaconda3\lib\site-packages\sqlalchemy\sql\elements.py", line 269, in _execute_on_connection
    return connection._execute_clauseelement(self, multiparams, params)
  File "C:\Users\romar\Anaconda3\lib\site-packages\sqlalchemy\engine\base.py", line 1060, in _execute_clauseelement
    compiled_sql, distilled_params
  File "C:\Users\romar\Anaconda3\lib\site-packages\sqlalchemy\engine\base.py", line 1200, in _execute_context
    context)
  File "C:\Users\romar\Anaconda3\lib\site-packages\sqlalchemy\engine\base.py", line 1413, in _handle_dbapi_exception
    exc_info
  File "C:\Users\romar\Anaconda3\lib\site-packages\sqlalchemy\util\compat.py", line 265, in raise_from_cause
    reraise(type(exception), exception, tb=exc_tb, cause=cause)
  File "C:\Users\romar\Anaconda3\lib\site-packages\sqlalchemy\util\compat.py", line 248, in reraise
    raise value.with_traceback(tb)
  File "C:\Users\romar\Anaconda3\lib\site-packages\sqlalchemy\engine\base.py", line 1193, in _execute_context
    context)
  File "C:\Users\romar\Anaconda3\lib\site-packages\sqlalchemy\engine\default.py", line 509, in do_execute
    cursor.execute(statement, parameters)
sqlalchemy.exc.OperationalError: (sqlite3.OperationalError) no such column: photos.created_date [SQL: 'SELECT photos.id AS photos_id, photos.about AS photos_about, photos.data AS photos_data, photos.created_date AS photos_created_date \nFROM photos \nWHERE photos.id = ?'] [parameters: (7,)] (Background on this error at: http://sqlalche.me/e/e3q8)
2020-04-17 01:55:39,148 ERROR flask.app Exception on /api/photos/7 [GET]
Traceback (most recent call last):
  File "C:\Users\romar\Anaconda3\lib\site-packages\sqlalchemy\engine\base.py", line 1193, in _execute_context
    context)
  File "C:\Users\romar\Anaconda3\lib\site-packages\sqlalchemy\engine\default.py", line 509, in do_execute
    cursor.execute(statement, parameters)
sqlite3.OperationalError: no such column: photos.created_date

The above exception was the direct cause of the following exception:

Traceback (most recent call last):
  File "C:\Users\romar\Anaconda3\lib\site-packages\flask\app.py", line 1813, in full_dispatch_request
    rv = self.dispatch_request()
  File "C:\Users\romar\Anaconda3\lib\site-packages\flask\app.py", line 1799, in dispatch_request
    return self.view_functions[rule.endpoint](**req.view_args)
  File "C:\Users\romar\Anaconda3\lib\site-packages\flask_restful\__init__.py", line 468, in wrapper
    resp = resource(*args, **kwargs)
  File "C:\Users\romar\Anaconda3\lib\site-packages\flask\views.py", line 88, in view
    return self.dispatch_request(*args, **kwargs)
  File "C:\Users\romar\Anaconda3\lib\site-packages\flask_restful\__init__.py", line 583, in dispatch_request
    resp = meth(*args, **kwargs)
  File "C:\NeoBrain\Server\resources\photos_resource.py", line 25, in get
    abort_if_photo_not_found(photo_id)
  File "C:\NeoBrain\Server\resources\photos_resource.py", line 14, in abort_if_photo_not_found
    photo = session.query(Photo).get(photo_id)
  File "C:\Users\romar\Anaconda3\lib\site-packages\sqlalchemy\orm\query.py", line 923, in get
    ident, loading.load_on_pk_identity)
  File "C:\Users\romar\Anaconda3\lib\site-packages\sqlalchemy\orm\query.py", line 1006, in _get_impl
    return db_load_fn(self, primary_key_identity)
  File "C:\Users\romar\Anaconda3\lib\site-packages\sqlalchemy\orm\loading.py", line 250, in load_on_pk_identity
    return q.one()
  File "C:\Users\romar\Anaconda3\lib\site-packages\sqlalchemy\orm\query.py", line 2947, in one
    ret = self.one_or_none()
  File "C:\Users\romar\Anaconda3\lib\site-packages\sqlalchemy\orm\query.py", line 2917, in one_or_none
    ret = list(self)
  File "C:\Users\romar\Anaconda3\lib\site-packages\sqlalchemy\orm\query.py", line 2988, in __iter__
    return self._execute_and_instances(context)
  File "C:\Users\romar\Anaconda3\lib\site-packages\sqlalchemy\orm\query.py", line 3011, in _execute_and_instances
    result = conn.execute(querycontext.statement, self._params)
  File "C:\Users\romar\Anaconda3\lib\site-packages\sqlalchemy\engine\base.py", line 948, in execute
    return meth(self, multiparams, params)
  File "C:\Users\romar\Anaconda3\lib\site-packages\sqlalchemy\sql\elements.py", line 269, in _execute_on_connection
    return connection._execute_clauseelement(self, multiparams, params)
  File "C:\Users\romar\Anaconda3\lib\site-packages\sqlalchemy\engine\base.py", line 1060, in _execute_clauseelement
    compiled_sql, distilled_params
  File "C:\Users\romar\Anaconda3\lib\site-packages\sqlalchemy\engine\base.py", line 1200, in _execute_context
    context)
  File "C:\Users\romar\Anaconda3\lib\site-packages\sqlalchemy\engine\base.py", line 1413, in _handle_dbapi_exception
    exc_info
  File "C:\Users\romar\Anaconda3\lib\site-packages\sqlalchemy\util\compat.py", line 265, in raise_from_cause
    reraise(type(exception), exception, tb=exc_tb, cause=cause)
  File "C:\Users\romar\Anaconda3\lib\site-packages\sqlalchemy\util\compat.py", line 248, in reraise
    raise value.with_traceback(tb)
  File "C:\Users\romar\Anaconda3\lib\site-packages\sqlalchemy\engine\base.py", line 1193, in _execute_context
    context)
  File "C:\Users\romar\Anaconda3\lib\site-packages\sqlalchemy\engine\default.py", line 509, in do_execute
    cursor.execute(statement, parameters)
sqlalchemy.exc.OperationalError: (sqlite3.OperationalError) no such column: photos.created_date [SQL: 'SELECT photos.id AS photos_id, photos.about AS photos_about, photos.data AS photos_data, photos.created_date AS photos_created_date \nFROM photos \nWHERE photos.id = ?'] [parameters: (7,)] (Background on this error at: http://sqlalche.me/e/e3q8)
2020-04-17 01:55:39,154 ERROR flask.app Exception on /api/photos/7 [GET]
Traceback (most recent call last):
  File "C:\Users\romar\Anaconda3\lib\site-packages\sqlalchemy\engine\base.py", line 1193, in _execute_context
    context)
  File "C:\Users\romar\Anaconda3\lib\site-packages\sqlalchemy\engine\default.py", line 509, in do_execute
    cursor.execute(statement, parameters)
sqlite3.OperationalError: no such column: photos.created_date

The above exception was the direct cause of the following exception:

Traceback (most recent call last):
  File "C:\Users\romar\Anaconda3\lib\site-packages\flask\app.py", line 1813, in full_dispatch_request
    rv = self.dispatch_request()
  File "C:\Users\romar\Anaconda3\lib\site-packages\flask\app.py", line 1799, in dispatch_request
    return self.view_functions[rule.endpoint](**req.view_args)
  File "C:\Users\romar\Anaconda3\lib\site-packages\flask_restful\__init__.py", line 468, in wrapper
    resp = resource(*args, **kwargs)
  File "C:\Users\romar\Anaconda3\lib\site-packages\flask\views.py", line 88, in view
    return self.dispatch_request(*args, **kwargs)
  File "C:\Users\romar\Anaconda3\lib\site-packages\flask_restful\__init__.py", line 583, in dispatch_request
    resp = meth(*args, **kwargs)
  File "C:\NeoBrain\Server\resources\photos_resource.py", line 25, in get
    abort_if_photo_not_found(photo_id)
  File "C:\NeoBrain\Server\resources\photos_resource.py", line 14, in abort_if_photo_not_found
    photo = session.query(Photo).get(photo_id)
  File "C:\Users\romar\Anaconda3\lib\site-packages\sqlalchemy\orm\query.py", line 923, in get
    ident, loading.load_on_pk_identity)
  File "C:\Users\romar\Anaconda3\lib\site-packages\sqlalchemy\orm\query.py", line 1006, in _get_impl
    return db_load_fn(self, primary_key_identity)
  File "C:\Users\romar\Anaconda3\lib\site-packages\sqlalchemy\orm\loading.py", line 250, in load_on_pk_identity
    return q.one()
  File "C:\Users\romar\Anaconda3\lib\site-packages\sqlalchemy\orm\query.py", line 2947, in one
    ret = self.one_or_none()
  File "C:\Users\romar\Anaconda3\lib\site-packages\sqlalchemy\orm\query.py", line 2917, in one_or_none
    ret = list(self)
  File "C:\Users\romar\Anaconda3\lib\site-packages\sqlalchemy\orm\query.py", line 2988, in __iter__
    return self._execute_and_instances(context)
  File "C:\Users\romar\Anaconda3\lib\site-packages\sqlalchemy\orm\query.py", line 3011, in _execute_and_instances
    result = conn.execute(querycontext.statement, self._params)
  File "C:\Users\romar\Anaconda3\lib\site-packages\sqlalchemy\engine\base.py", line 948, in execute
    return meth(self, multiparams, params)
  File "C:\Users\romar\Anaconda3\lib\site-packages\sqlalchemy\sql\elements.py", line 269, in _execute_on_connection
    return connection._execute_clauseelement(self, multiparams, params)
  File "C:\Users\romar\Anaconda3\lib\site-packages\sqlalchemy\engine\base.py", line 1060, in _execute_clauseelement
    compiled_sql, distilled_params
  File "C:\Users\romar\Anaconda3\lib\site-packages\sqlalchemy\engine\base.py", line 1200, in _execute_context
    context)
  File "C:\Users\romar\Anaconda3\lib\site-packages\sqlalchemy\engine\base.py", line 1413, in _handle_dbapi_exception
    exc_info
  File "C:\Users\romar\Anaconda3\lib\site-packages\sqlalchemy\util\compat.py", line 265, in raise_from_cause
    reraise(type(exception), exception, tb=exc_tb, cause=cause)
  File "C:\Users\romar\Anaconda3\lib\site-packages\sqlalchemy\util\compat.py", line 248, in reraise
    raise value.with_traceback(tb)
  File "C:\Users\romar\Anaconda3\lib\site-packages\sqlalchemy\engine\base.py", line 1193, in _execute_context
    context)
  File "C:\Users\romar\Anaconda3\lib\site-packages\sqlalchemy\engine\default.py", line 509, in do_execute
    cursor.execute(statement, parameters)
sqlalchemy.exc.OperationalError: (sqlite3.OperationalError) no such column: photos.created_date [SQL: 'SELECT photos.id AS photos_id, photos.about AS photos_about, photos.data AS photos_data, photos.created_date AS photos_created_date \nFROM photos \nWHERE photos.id = ?'] [parameters: (7,)] (Background on this error at: http://sqlalche.me/e/e3q8)
2020-04-17 01:55:39,157 ERROR flask.app Exception on /api/photos/7 [GET]
Traceback (most recent call last):
  File "C:\Users\romar\Anaconda3\lib\site-packages\sqlalchemy\engine\base.py", line 1193, in _execute_context
    context)
  File "C:\Users\romar\Anaconda3\lib\site-packages\sqlalchemy\engine\default.py", line 509, in do_execute
    cursor.execute(statement, parameters)
sqlite3.OperationalError: no such column: photos.created_date

The above exception was the direct cause of the following exception:

Traceback (most recent call last):
  File "C:\Users\romar\Anaconda3\lib\site-packages\flask\app.py", line 1813, in full_dispatch_request
    rv = self.dispatch_request()
  File "C:\Users\romar\Anaconda3\lib\site-packages\flask\app.py", line 1799, in dispatch_request
    return self.view_functions[rule.endpoint](**req.view_args)
  File "C:\Users\romar\Anaconda3\lib\site-packages\flask_restful\__init__.py", line 468, in wrapper
    resp = resource(*args, **kwargs)
  File "C:\Users\romar\Anaconda3\lib\site-packages\flask\views.py", line 88, in view
    return self.dispatch_request(*args, **kwargs)
  File "C:\Users\romar\Anaconda3\lib\site-packages\flask_restful\__init__.py", line 583, in dispatch_request
    resp = meth(*args, **kwargs)
  File "C:\NeoBrain\Server\resources\photos_resource.py", line 25, in get
    abort_if_photo_not_found(photo_id)
  File "C:\NeoBrain\Server\resources\photos_resource.py", line 14, in abort_if_photo_not_found
    photo = session.query(Photo).get(photo_id)
  File "C:\Users\romar\Anaconda3\lib\site-packages\sqlalchemy\orm\query.py", line 923, in get
    ident, loading.load_on_pk_identity)
  File "C:\Users\romar\Anaconda3\lib\site-packages\sqlalchemy\orm\query.py", line 1006, in _get_impl
    return db_load_fn(self, primary_key_identity)
  File "C:\Users\romar\Anaconda3\lib\site-packages\sqlalchemy\orm\loading.py", line 250, in load_on_pk_identity
    return q.one()
  File "C:\Users\romar\Anaconda3\lib\site-packages\sqlalchemy\orm\query.py", line 2947, in one
    ret = self.one_or_none()
  File "C:\Users\romar\Anaconda3\lib\site-packages\sqlalchemy\orm\query.py", line 2917, in one_or_none
    ret = list(self)
  File "C:\Users\romar\Anaconda3\lib\site-packages\sqlalchemy\orm\query.py", line 2988, in __iter__
    return self._execute_and_instances(context)
  File "C:\Users\romar\Anaconda3\lib\site-packages\sqlalchemy\orm\query.py", line 3011, in _execute_and_instances
    result = conn.execute(querycontext.statement, self._params)
  File "C:\Users\romar\Anaconda3\lib\site-packages\sqlalchemy\engine\base.py", line 948, in execute
    return meth(self, multiparams, params)
  File "C:\Users\romar\Anaconda3\lib\site-packages\sqlalchemy\sql\elements.py", line 269, in _execute_on_connection
    return connection._execute_clauseelement(self, multiparams, params)
  File "C:\Users\romar\Anaconda3\lib\site-packages\sqlalchemy\engine\base.py", line 1060, in _execute_clauseelement
    compiled_sql, distilled_params
  File "C:\Users\romar\Anaconda3\lib\site-packages\sqlalchemy\engine\base.py", line 1200, in _execute_context
    context)
  File "C:\Users\romar\Anaconda3\lib\site-packages\sqlalchemy\engine\base.py", line 1413, in _handle_dbapi_exception
    exc_info
  File "C:\Users\romar\Anaconda3\lib\site-packages\sqlalchemy\util\compat.py", line 265, in raise_from_cause
    reraise(type(exception), exception, tb=exc_tb, cause=cause)
  File "C:\Users\romar\Anaconda3\lib\site-packages\sqlalchemy\util\compat.py", line 248, in reraise
    raise value.with_traceback(tb)
  File "C:\Users\romar\Anaconda3\lib\site-packages\sqlalchemy\engine\base.py", line 1193, in _execute_context
    context)
  File "C:\Users\romar\Anaconda3\lib\site-packages\sqlalchemy\engine\default.py", line 509, in do_execute
    cursor.execute(statement, parameters)
sqlalchemy.exc.OperationalError: (sqlite3.OperationalError) no such column: photos.created_date [SQL: 'SELECT photos.id AS photos_id, photos.about AS photos_about, photos.data AS photos_data, photos.created_date AS photos_created_date \nFROM photos \nWHERE photos.id = ?'] [parameters: (7,)] (Background on this error at: http://sqlalche.me/e/e3q8)
2020-04-17 01:55:39,157 ERROR flask.app Exception on /api/photos/7 [GET]
Traceback (most recent call last):
  File "C:\Users\romar\Anaconda3\lib\site-packages\sqlalchemy\engine\base.py", line 1193, in _execute_context
    context)
  File "C:\Users\romar\Anaconda3\lib\site-packages\sqlalchemy\engine\default.py", line 509, in do_execute
    cursor.execute(statement, parameters)
sqlite3.OperationalError: no such column: photos.created_date

The above exception was the direct cause of the following exception:

Traceback (most recent call last):
  File "C:\Users\romar\Anaconda3\lib\site-packages\flask\app.py", line 1813, in full_dispatch_request
    rv = self.dispatch_request()
  File "C:\Users\romar\Anaconda3\lib\site-packages\flask\app.py", line 1799, in dispatch_request
    return self.view_functions[rule.endpoint](**req.view_args)
  File "C:\Users\romar\Anaconda3\lib\site-packages\flask_restful\__init__.py", line 468, in wrapper
    resp = resource(*args, **kwargs)
  File "C:\Users\romar\Anaconda3\lib\site-packages\flask\views.py", line 88, in view
    return self.dispatch_request(*args, **kwargs)
  File "C:\Users\romar\Anaconda3\lib\site-packages\flask_restful\__init__.py", line 583, in dispatch_request
    resp = meth(*args, **kwargs)
  File "C:\NeoBrain\Server\resources\photos_resource.py", line 25, in get
    abort_if_photo_not_found(photo_id)
  File "C:\NeoBrain\Server\resources\photos_resource.py", line 14, in abort_if_photo_not_found
    photo = session.query(Photo).get(photo_id)
  File "C:\Users\romar\Anaconda3\lib\site-packages\sqlalchemy\orm\query.py", line 923, in get
    ident, loading.load_on_pk_identity)
  File "C:\Users\romar\Anaconda3\lib\site-packages\sqlalchemy\orm\query.py", line 1006, in _get_impl
    return db_load_fn(self, primary_key_identity)
  File "C:\Users\romar\Anaconda3\lib\site-packages\sqlalchemy\orm\loading.py", line 250, in load_on_pk_identity
    return q.one()
  File "C:\Users\romar\Anaconda3\lib\site-packages\sqlalchemy\orm\query.py", line 2947, in one
    ret = self.one_or_none()
  File "C:\Users\romar\Anaconda3\lib\site-packages\sqlalchemy\orm\query.py", line 2917, in one_or_none
    ret = list(self)
  File "C:\Users\romar\Anaconda3\lib\site-packages\sqlalchemy\orm\query.py", line 2988, in __iter__
    return self._execute_and_instances(context)
  File "C:\Users\romar\Anaconda3\lib\site-packages\sqlalchemy\orm\query.py", line 3011, in _execute_and_instances
    result = conn.execute(querycontext.statement, self._params)
  File "C:\Users\romar\Anaconda3\lib\site-packages\sqlalchemy\engine\base.py", line 948, in execute
    return meth(self, multiparams, params)
  File "C:\Users\romar\Anaconda3\lib\site-packages\sqlalchemy\sql\elements.py", line 269, in _execute_on_connection
    return connection._execute_clauseelement(self, multiparams, params)
  File "C:\Users\romar\Anaconda3\lib\site-packages\sqlalchemy\engine\base.py", line 1060, in _execute_clauseelement
    compiled_sql, distilled_params
  File "C:\Users\romar\Anaconda3\lib\site-packages\sqlalchemy\engine\base.py", line 1200, in _execute_context
    context)
  File "C:\Users\romar\Anaconda3\lib\site-packages\sqlalchemy\engine\base.py", line 1413, in _handle_dbapi_exception
    exc_info
  File "C:\Users\romar\Anaconda3\lib\site-packages\sqlalchemy\util\compat.py", line 265, in raise_from_cause
    reraise(type(exception), exception, tb=exc_tb, cause=cause)
  File "C:\Users\romar\Anaconda3\lib\site-packages\sqlalchemy\util\compat.py", line 248, in reraise
    raise value.with_traceback(tb)
  File "C:\Users\romar\Anaconda3\lib\site-packages\sqlalchemy\engine\base.py", line 1193, in _execute_context
    context)
  File "C:\Users\romar\Anaconda3\lib\site-packages\sqlalchemy\engine\default.py", line 509, in do_execute
    cursor.execute(statement, parameters)
sqlalchemy.exc.OperationalError: (sqlite3.OperationalError) no such column: photos.created_date [SQL: 'SELECT photos.id AS photos_id, photos.about AS photos_about, photos.data AS photos_data, photos.created_date AS photos_created_date \nFROM photos \nWHERE photos.id = ?'] [parameters: (7,)] (Background on this error at: http://sqlalche.me/e/e3q8)
2020-04-17 01:55:40,565 ERROR flask.app Exception on /api/photos/7 [GET]
Traceback (most recent call last):
  File "C:\Users\romar\Anaconda3\lib\site-packages\sqlalchemy\engine\base.py", line 1193, in _execute_context
    context)
  File "C:\Users\romar\Anaconda3\lib\site-packages\sqlalchemy\engine\default.py", line 509, in do_execute
    cursor.execute(statement, parameters)
sqlite3.OperationalError: no such column: photos.created_date

The above exception was the direct cause of the following exception:

Traceback (most recent call last):
  File "C:\Users\romar\Anaconda3\lib\site-packages\flask\app.py", line 1813, in full_dispatch_request
    rv = self.dispatch_request()
  File "C:\Users\romar\Anaconda3\lib\site-packages\flask\app.py", line 1799, in dispatch_request
    return self.view_functions[rule.endpoint](**req.view_args)
  File "C:\Users\romar\Anaconda3\lib\site-packages\flask_restful\__init__.py", line 468, in wrapper
    resp = resource(*args, **kwargs)
  File "C:\Users\romar\Anaconda3\lib\site-packages\flask\views.py", line 88, in view
    return self.dispatch_request(*args, **kwargs)
  File "C:\Users\romar\Anaconda3\lib\site-packages\flask_restful\__init__.py", line 583, in dispatch_request
    resp = meth(*args, **kwargs)
  File "C:\NeoBrain\Server\resources\photos_resource.py", line 25, in get
    abort_if_photo_not_found(photo_id)
  File "C:\NeoBrain\Server\resources\photos_resource.py", line 14, in abort_if_photo_not_found
    photo = session.query(Photo).get(photo_id)
  File "C:\Users\romar\Anaconda3\lib\site-packages\sqlalchemy\orm\query.py", line 923, in get
    ident, loading.load_on_pk_identity)
  File "C:\Users\romar\Anaconda3\lib\site-packages\sqlalchemy\orm\query.py", line 1006, in _get_impl
    return db_load_fn(self, primary_key_identity)
  File "C:\Users\romar\Anaconda3\lib\site-packages\sqlalchemy\orm\loading.py", line 250, in load_on_pk_identity
    return q.one()
  File "C:\Users\romar\Anaconda3\lib\site-packages\sqlalchemy\orm\query.py", line 2947, in one
    ret = self.one_or_none()
  File "C:\Users\romar\Anaconda3\lib\site-packages\sqlalchemy\orm\query.py", line 2917, in one_or_none
    ret = list(self)
  File "C:\Users\romar\Anaconda3\lib\site-packages\sqlalchemy\orm\query.py", line 2988, in __iter__
    return self._execute_and_instances(context)
  File "C:\Users\romar\Anaconda3\lib\site-packages\sqlalchemy\orm\query.py", line 3011, in _execute_and_instances
    result = conn.execute(querycontext.statement, self._params)
  File "C:\Users\romar\Anaconda3\lib\site-packages\sqlalchemy\engine\base.py", line 948, in execute
    return meth(self, multiparams, params)
  File "C:\Users\romar\Anaconda3\lib\site-packages\sqlalchemy\sql\elements.py", line 269, in _execute_on_connection
    return connection._execute_clauseelement(self, multiparams, params)
  File "C:\Users\romar\Anaconda3\lib\site-packages\sqlalchemy\engine\base.py", line 1060, in _execute_clauseelement
    compiled_sql, distilled_params
  File "C:\Users\romar\Anaconda3\lib\site-packages\sqlalchemy\engine\base.py", line 1200, in _execute_context
    context)
  File "C:\Users\romar\Anaconda3\lib\site-packages\sqlalchemy\engine\base.py", line 1413, in _handle_dbapi_exception
    exc_info
  File "C:\Users\romar\Anaconda3\lib\site-packages\sqlalchemy\util\compat.py", line 265, in raise_from_cause
    reraise(type(exception), exception, tb=exc_tb, cause=cause)
  File "C:\Users\romar\Anaconda3\lib\site-packages\sqlalchemy\util\compat.py", line 248, in reraise
    raise value.with_traceback(tb)
  File "C:\Users\romar\Anaconda3\lib\site-packages\sqlalchemy\engine\base.py", line 1193, in _execute_context
    context)
  File "C:\Users\romar\Anaconda3\lib\site-packages\sqlalchemy\engine\default.py", line 509, in do_execute
    cursor.execute(statement, parameters)
sqlalchemy.exc.OperationalError: (sqlite3.OperationalError) no such column: photos.created_date [SQL: 'SELECT photos.id AS photos_id, photos.about AS photos_about, photos.data AS photos_data, photos.created_date AS photos_created_date \nFROM photos \nWHERE photos.id = ?'] [parameters: (7,)] (Background on this error at: http://sqlalche.me/e/e3q8)
